INFO:discord.client:logging in using static token
INFO:discord.gateway:Created websocket connected to wss://gateway.discord.gg?encoding=json&v=6&compress=zlib-stream
INFO:discord.gateway:Shard ID None has sent the IDENTIFY payload.
INFO:discord.gateway:Shard ID None has connected to Gateway: ["gateway-prd-main-1bq1",{"micros":78706,"calls":["discord-sessions-prd-1-41",{"micros":77442,"calls":["start_session",{"micros":50870,"calls":["api-prd-main-fpch",{"micros":46209,"calls":["get_user",{"micros":4703},"add_authorized_ip",{"micros":2998},"get_guilds",{"micros":1646},"coros_wait",{"micros":0}]}]},"guilds_connect",{"micros":1,"calls":[]},"presence_connect",{"micros":13181,"calls":[]}]}]}] (Session ID: e0b22e865d74ffe4bca48d1b4f50ad4f).
INFO:discord.client:Cleaning up event loop.
INFO:discord.client:Cleaning up after 1 tasks.
ERROR:asyncio:Task exception was never retrieved
future: <Task finished coro=<Client.start() done, defined at C:\Users\Salanski\AppData\Local\Programs\Python\Python36\lib\site-packages\discord\client.py:500> exception=TypeError("__new__() got an unexpected keyword argument 'deny_new'",)>
Traceback (most recent call last):
  File "C:\Users\Salanski\AppData\Local\Programs\Python\Python36\lib\site-packages\discord\client.py", line 509, in start
    await self.connect(reconnect=reconnect)
  File "C:\Users\Salanski\AppData\Local\Programs\Python\Python36\lib\site-packages\discord\client.py", line 431, in connect
    await self._connect()
  File "C:\Users\Salanski\AppData\Local\Programs\Python\Python36\lib\site-packages\discord\client.py", line 395, in _connect
    await self.ws.poll_event()
  File "C:\Users\Salanski\AppData\Local\Programs\Python\Python36\lib\site-packages\discord\gateway.py", line 465, in poll_event
    await self.received_message(msg)
  File "C:\Users\Salanski\AppData\Local\Programs\Python\Python36\lib\site-packages\discord\gateway.py", line 419, in received_message
    func(data)
  File "C:\Users\Salanski\AppData\Local\Programs\Python\Python36\lib\site-packages\discord\state.py", line 660, in parse_guild_create
    guild = self._get_create_guild(data)
  File "C:\Users\Salanski\AppData\Local\Programs\Python\Python36\lib\site-packages\discord\state.py", line 635, in _get_create_guild
    guild._from_data(data)
  File "C:\Users\Salanski\AppData\Local\Programs\Python\Python36\lib\site-packages\discord\guild.py", line 245, in _from_data
    self._sync(guild)
  File "C:\Users\Salanski\AppData\Local\Programs\Python\Python36\lib\site-packages\discord\guild.py", line 272, in _sync
    self._add_channel(TextChannel(guild=self, data=c, state=self._state))
  File "C:\Users\Salanski\AppData\Local\Programs\Python\Python36\lib\site-packages\discord\channel.py", line 107, in __init__
    self._update(guild, data)
  File "C:\Users\Salanski\AppData\Local\Programs\Python\Python36\lib\site-packages\discord\channel.py", line 123, in _update
    self._fill_overwrites(data)
  File "C:\Users\Salanski\AppData\Local\Programs\Python\Python36\lib\site-packages\discord\abc.py", line 271, in _fill_overwrites
    self._overwrites.append(_Overwrites(id=overridden_id, **overridden))
TypeError: __new__() got an unexpected keyword argument 'deny_new'
