INFO:discord.client:logging in using static token
INFO:discord.gateway:Created websocket connected to wss://gateway.discord.gg?encoding=json&v=6&compress=zlib-stream
INFO:discord.gateway:Shard ID None has sent the IDENTIFY payload.
INFO:discord.gateway:Shard ID None has connected to Gateway: gateway-prd-main-qv96, discord-sessions-prd-1-11 (Session ID: fc280c7397cb574ddb250dbe6309234e).
INFO:root:Logging in as:Party-Bot : 438288661398683650
WARNING:discord.gateway:Unknown event PRESENCES_REPLACE.
INFO:discord.client:logging in using static token
INFO:discord.gateway:Created websocket connected to wss://gateway.discord.gg?encoding=json&v=6&compress=zlib-stream
INFO:discord.gateway:Shard ID None has sent the IDENTIFY payload.
INFO:discord.gateway:Shard ID None has connected to Gateway: gateway-prd-main-t0lh, discord-sessions-prd-1-21 (Session ID: 684b42c106be8323dc961fcafd1e746f).
INFO:root:Logging in as:Party-Bot : 438288661398683650
INFO:root:{0.command.name} command : from {0.message.author.name}
INFO:discord.client:logging in using static token
INFO:discord.gateway:Created websocket connected to wss://gateway.discord.gg?encoding=json&v=6&compress=zlib-stream
INFO:discord.gateway:Shard ID None has sent the IDENTIFY payload.
INFO:discord.gateway:Shard ID None has connected to Gateway: gateway-prd-main-nzxs, discord-sessions-prd-1-23 (Session ID: 11182795ed896008f7a26a9106c08f4d).
INFO:root:Logging in as:Party-Bot : 438288661398683650
INFO:root:hi command : from Scarybone
INFO:discord.client:logging in using static token
INFO:discord.gateway:Created websocket connected to wss://gateway.discord.gg?encoding=json&v=6&compress=zlib-stream
INFO:discord.gateway:Shard ID None has sent the IDENTIFY payload.
INFO:discord.gateway:Shard ID None has connected to Gateway: gateway-prd-main-zw0f, discord-sessions-prd-1-13 (Session ID: d79ffbcb8985c7d8163ad449e2d05e09).
INFO:root:Logging in as:Party-Bot : 438288661398683650
INFO:root:Received |hi| command from |Scarybone|
INFO:root:Received |help| command from |Scarybone|
INFO:discord.client:logging in using static token
INFO:discord.gateway:Created websocket connected to wss://gateway.discord.gg?encoding=json&v=6&compress=zlib-stream
INFO:discord.gateway:Shard ID None has sent the IDENTIFY payload.
INFO:discord.gateway:Shard ID None has connected to Gateway: gateway-prd-main-zml2, discord-sessions-prd-1-25 (Session ID: 77f096c2be32436807ff8d64cfd8cb67).
INFO:root:Logging in as:Party-Bot : 438288661398683650
INFO:discord.client:logging in using static token
INFO:discord.gateway:Created websocket connected to wss://gateway.discord.gg?encoding=json&v=6&compress=zlib-stream
INFO:discord.gateway:Shard ID None has sent the IDENTIFY payload.
INFO:discord.gateway:Shard ID None has connected to Gateway: gateway-prd-main-s0w2, discord-sessions-prd-1-6 (Session ID: cb012aea109780824d7475f28de212c8).
INFO:root:Logging in as:Party-Bot : 438288661398683650
WARNING:googleapiclient.discovery_cache:file_cache is unavailable when using oauth2client >= 4.0.0 or google-auth
Traceback (most recent call last):
  File "C:\Users\scary\AppData\Local\Programs\Python\Python36\lib\site-packages\googleapiclient\discovery_cache\__init__.py", line 36, in autodetect
    from google.appengine.api import memcache
ModuleNotFoundError: No module named 'google.appengine'

During handling of the above exception, another exception occurred:

Traceback (most recent call last):
  File "C:\Users\scary\AppData\Local\Programs\Python\Python36\lib\site-packages\googleapiclient\discovery_cache\file_cache.py", line 33, in <module>
    from oauth2client.contrib.locked_file import LockedFile
ModuleNotFoundError: No module named 'oauth2client'

During handling of the above exception, another exception occurred:

Traceback (most recent call last):
  File "C:\Users\scary\AppData\Local\Programs\Python\Python36\lib\site-packages\googleapiclient\discovery_cache\file_cache.py", line 37, in <module>
    from oauth2client.locked_file import LockedFile
ModuleNotFoundError: No module named 'oauth2client'

During handling of the above exception, another exception occurred:

Traceback (most recent call last):
  File "C:\Users\scary\AppData\Local\Programs\Python\Python36\lib\site-packages\googleapiclient\discovery_cache\__init__.py", line 41, in autodetect
    from . import file_cache
  File "C:\Users\scary\AppData\Local\Programs\Python\Python36\lib\site-packages\googleapiclient\discovery_cache\file_cache.py", line 41, in <module>
    'file_cache is unavailable when using oauth2client >= 4.0.0 or google-auth')
ImportError: file_cache is unavailable when using oauth2client >= 4.0.0 or google-auth
INFO:googleapiclient.discovery:URL being requested: GET https://www.googleapis.com/discovery/v1/apis/sheets/v4/rest
INFO:root:Received |xp| command from |Scarybone|
INFO:discord.client:logging in using static token
INFO:discord.gateway:Created websocket connected to wss://gateway.discord.gg?encoding=json&v=6&compress=zlib-stream
INFO:discord.gateway:Shard ID None has sent the IDENTIFY payload.
INFO:discord.gateway:Shard ID None has connected to Gateway: gateway-prd-main-lcsr, discord-sessions-prd-1-1 (Session ID: a36a39c4267eec755ae25f7c9599a01a).
INFO:root:Logging in as:Party-Bot : 438288661398683650
WARNING:googleapiclient.discovery_cache:file_cache is unavailable when using oauth2client >= 4.0.0 or google-auth
Traceback (most recent call last):
  File "C:\Users\scary\AppData\Local\Programs\Python\Python36\lib\site-packages\googleapiclient\discovery_cache\__init__.py", line 36, in autodetect
    from google.appengine.api import memcache
ModuleNotFoundError: No module named 'google.appengine'

During handling of the above exception, another exception occurred:

Traceback (most recent call last):
  File "C:\Users\scary\AppData\Local\Programs\Python\Python36\lib\site-packages\googleapiclient\discovery_cache\file_cache.py", line 33, in <module>
    from oauth2client.contrib.locked_file import LockedFile
ModuleNotFoundError: No module named 'oauth2client'

During handling of the above exception, another exception occurred:

Traceback (most recent call last):
  File "C:\Users\scary\AppData\Local\Programs\Python\Python36\lib\site-packages\googleapiclient\discovery_cache\file_cache.py", line 37, in <module>
    from oauth2client.locked_file import LockedFile
ModuleNotFoundError: No module named 'oauth2client'

During handling of the above exception, another exception occurred:

Traceback (most recent call last):
  File "C:\Users\scary\AppData\Local\Programs\Python\Python36\lib\site-packages\googleapiclient\discovery_cache\__init__.py", line 41, in autodetect
    from . import file_cache
  File "C:\Users\scary\AppData\Local\Programs\Python\Python36\lib\site-packages\googleapiclient\discovery_cache\file_cache.py", line 41, in <module>
    'file_cache is unavailable when using oauth2client >= 4.0.0 or google-auth')
ImportError: file_cache is unavailable when using oauth2client >= 4.0.0 or google-auth
INFO:googleapiclient.discovery:URL being requested: GET https://www.googleapis.com/discovery/v1/apis/sheets/v4/rest
INFO:root:Received |xp| command from |Scarybone|
INFO:root:Received |xp| command from |Scarybone|
INFO:discord.client:logging in using static token
INFO:discord.gateway:Created websocket connected to wss://gateway.discord.gg?encoding=json&v=6&compress=zlib-stream
INFO:discord.gateway:Shard ID None has sent the IDENTIFY payload.
INFO:discord.gateway:Shard ID None has connected to Gateway: gateway-prd-main-7d6c, discord-sessions-prd-1-11 (Session ID: 30e93c7a295f3c9f0cc54d5c4b11f274).
INFO:root:Logging in as:Party-Bot : 438288661398683650
WARNING:googleapiclient.discovery_cache:file_cache is unavailable when using oauth2client >= 4.0.0 or google-auth
Traceback (most recent call last):
  File "C:\Users\scary\AppData\Local\Programs\Python\Python36\lib\site-packages\googleapiclient\discovery_cache\__init__.py", line 36, in autodetect
    from google.appengine.api import memcache
ModuleNotFoundError: No module named 'google.appengine'

During handling of the above exception, another exception occurred:

Traceback (most recent call last):
  File "C:\Users\scary\AppData\Local\Programs\Python\Python36\lib\site-packages\googleapiclient\discovery_cache\file_cache.py", line 33, in <module>
    from oauth2client.contrib.locked_file import LockedFile
ModuleNotFoundError: No module named 'oauth2client'

During handling of the above exception, another exception occurred:

Traceback (most recent call last):
  File "C:\Users\scary\AppData\Local\Programs\Python\Python36\lib\site-packages\googleapiclient\discovery_cache\file_cache.py", line 37, in <module>
    from oauth2client.locked_file import LockedFile
ModuleNotFoundError: No module named 'oauth2client'

During handling of the above exception, another exception occurred:

Traceback (most recent call last):
  File "C:\Users\scary\AppData\Local\Programs\Python\Python36\lib\site-packages\googleapiclient\discovery_cache\__init__.py", line 41, in autodetect
    from . import file_cache
  File "C:\Users\scary\AppData\Local\Programs\Python\Python36\lib\site-packages\googleapiclient\discovery_cache\file_cache.py", line 41, in <module>
    'file_cache is unavailable when using oauth2client >= 4.0.0 or google-auth')
ImportError: file_cache is unavailable when using oauth2client >= 4.0.0 or google-auth
INFO:googleapiclient.discovery:URL being requested: GET https://www.googleapis.com/discovery/v1/apis/sheets/v4/rest
INFO:root:Received |xp| command from |Scarybone|
INFO:discord.client:logging in using static token
INFO:discord.gateway:Created websocket connected to wss://gateway.discord.gg?encoding=json&v=6&compress=zlib-stream
INFO:discord.gateway:Shard ID None has sent the IDENTIFY payload.
INFO:discord.gateway:Shard ID None has connected to Gateway: gateway-prd-main-9ljs, discord-sessions-prd-1-27 (Session ID: da6c6ce8424153f2eea62e5dd8f54005).
INFO:root:Logging in as:Party-Bot : 438288661398683650
WARNING:googleapiclient.discovery_cache:file_cache is unavailable when using oauth2client >= 4.0.0 or google-auth
Traceback (most recent call last):
  File "C:\Users\scary\AppData\Local\Programs\Python\Python36\lib\site-packages\googleapiclient\discovery_cache\__init__.py", line 36, in autodetect
    from google.appengine.api import memcache
ModuleNotFoundError: No module named 'google.appengine'

During handling of the above exception, another exception occurred:

Traceback (most recent call last):
  File "C:\Users\scary\AppData\Local\Programs\Python\Python36\lib\site-packages\googleapiclient\discovery_cache\file_cache.py", line 33, in <module>
    from oauth2client.contrib.locked_file import LockedFile
ModuleNotFoundError: No module named 'oauth2client'

During handling of the above exception, another exception occurred:

Traceback (most recent call last):
  File "C:\Users\scary\AppData\Local\Programs\Python\Python36\lib\site-packages\googleapiclient\discovery_cache\file_cache.py", line 37, in <module>
    from oauth2client.locked_file import LockedFile
ModuleNotFoundError: No module named 'oauth2client'

During handling of the above exception, another exception occurred:

Traceback (most recent call last):
  File "C:\Users\scary\AppData\Local\Programs\Python\Python36\lib\site-packages\googleapiclient\discovery_cache\__init__.py", line 41, in autodetect
    from . import file_cache
  File "C:\Users\scary\AppData\Local\Programs\Python\Python36\lib\site-packages\googleapiclient\discovery_cache\file_cache.py", line 41, in <module>
    'file_cache is unavailable when using oauth2client >= 4.0.0 or google-auth')
ImportError: file_cache is unavailable when using oauth2client >= 4.0.0 or google-auth
INFO:googleapiclient.discovery:URL being requested: GET https://www.googleapis.com/discovery/v1/apis/sheets/v4/rest
INFO:root:Received |xp| command from |Scarybone|
INFO:discord.client:logging in using static token
INFO:discord.gateway:Created websocket connected to wss://gateway.discord.gg?encoding=json&v=6&compress=zlib-stream
INFO:discord.gateway:Shard ID None has sent the IDENTIFY payload.
INFO:discord.gateway:Shard ID None has connected to Gateway: gateway-prd-main-v1xc, discord-sessions-prd-1-25 (Session ID: ddd6303442ca5aa84bf4224e9d64e707).
INFO:root:Logging in as:Party-Bot : 438288661398683650
WARNING:googleapiclient.discovery_cache:file_cache is unavailable when using oauth2client >= 4.0.0 or google-auth
Traceback (most recent call last):
  File "C:\Users\scary\AppData\Local\Programs\Python\Python36\lib\site-packages\googleapiclient\discovery_cache\__init__.py", line 36, in autodetect
    from google.appengine.api import memcache
ModuleNotFoundError: No module named 'google.appengine'

During handling of the above exception, another exception occurred:

Traceback (most recent call last):
  File "C:\Users\scary\AppData\Local\Programs\Python\Python36\lib\site-packages\googleapiclient\discovery_cache\file_cache.py", line 33, in <module>
    from oauth2client.contrib.locked_file import LockedFile
ModuleNotFoundError: No module named 'oauth2client'

During handling of the above exception, another exception occurred:

Traceback (most recent call last):
  File "C:\Users\scary\AppData\Local\Programs\Python\Python36\lib\site-packages\googleapiclient\discovery_cache\file_cache.py", line 37, in <module>
    from oauth2client.locked_file import LockedFile
ModuleNotFoundError: No module named 'oauth2client'

During handling of the above exception, another exception occurred:

Traceback (most recent call last):
  File "C:\Users\scary\AppData\Local\Programs\Python\Python36\lib\site-packages\googleapiclient\discovery_cache\__init__.py", line 41, in autodetect
    from . import file_cache
  File "C:\Users\scary\AppData\Local\Programs\Python\Python36\lib\site-packages\googleapiclient\discovery_cache\file_cache.py", line 41, in <module>
    'file_cache is unavailable when using oauth2client >= 4.0.0 or google-auth')
ImportError: file_cache is unavailable when using oauth2client >= 4.0.0 or google-auth
INFO:googleapiclient.discovery:URL being requested: GET https://www.googleapis.com/discovery/v1/apis/sheets/v4/rest
INFO:root:Received |xp| command from |Scarybone|
INFO:root:Received |xp| command from |Scarybone|
INFO:discord.client:logging in using static token
INFO:discord.gateway:Created websocket connected to wss://gateway.discord.gg?encoding=json&v=6&compress=zlib-stream
INFO:discord.gateway:Shard ID None has sent the IDENTIFY payload.
INFO:discord.gateway:Shard ID None has connected to Gateway: gateway-prd-main-lsm2, discord-sessions-prd-1-1 (Session ID: 08916902018d9f58ca4b2f52d5626457).
INFO:root:Logging in as:Party-Bot : 438288661398683650
WARNING:googleapiclient.discovery_cache:file_cache is unavailable when using oauth2client >= 4.0.0 or google-auth
Traceback (most recent call last):
  File "C:\Users\scary\AppData\Local\Programs\Python\Python36\lib\site-packages\googleapiclient\discovery_cache\__init__.py", line 36, in autodetect
    from google.appengine.api import memcache
ModuleNotFoundError: No module named 'google.appengine'

During handling of the above exception, another exception occurred:

Traceback (most recent call last):
  File "C:\Users\scary\AppData\Local\Programs\Python\Python36\lib\site-packages\googleapiclient\discovery_cache\file_cache.py", line 33, in <module>
    from oauth2client.contrib.locked_file import LockedFile
ModuleNotFoundError: No module named 'oauth2client'

During handling of the above exception, another exception occurred:

Traceback (most recent call last):
  File "C:\Users\scary\AppData\Local\Programs\Python\Python36\lib\site-packages\googleapiclient\discovery_cache\file_cache.py", line 37, in <module>
    from oauth2client.locked_file import LockedFile
ModuleNotFoundError: No module named 'oauth2client'

During handling of the above exception, another exception occurred:

Traceback (most recent call last):
  File "C:\Users\scary\AppData\Local\Programs\Python\Python36\lib\site-packages\googleapiclient\discovery_cache\__init__.py", line 41, in autodetect
    from . import file_cache
  File "C:\Users\scary\AppData\Local\Programs\Python\Python36\lib\site-packages\googleapiclient\discovery_cache\file_cache.py", line 41, in <module>
    'file_cache is unavailable when using oauth2client >= 4.0.0 or google-auth')
ImportError: file_cache is unavailable when using oauth2client >= 4.0.0 or google-auth
INFO:googleapiclient.discovery:URL being requested: GET https://www.googleapis.com/discovery/v1/apis/sheets/v4/rest
INFO:root:Received |xp| command from |Scarybone|
INFO:discord.client:logging in using static token
INFO:discord.gateway:Created websocket connected to wss://gateway.discord.gg?encoding=json&v=6&compress=zlib-stream
INFO:discord.gateway:Shard ID None has sent the IDENTIFY payload.
INFO:discord.gateway:Shard ID None has connected to Gateway: gateway-prd-main-2zz6, discord-sessions-prd-1-12 (Session ID: 6795a4f78c26d2fe5458e1bdf344db9a).
INFO:root:Logging in as:Party-Bot : 438288661398683650
WARNING:googleapiclient.discovery_cache:file_cache is unavailable when using oauth2client >= 4.0.0 or google-auth
Traceback (most recent call last):
  File "C:\Users\scary\AppData\Local\Programs\Python\Python36\lib\site-packages\googleapiclient\discovery_cache\__init__.py", line 36, in autodetect
    from google.appengine.api import memcache
ModuleNotFoundError: No module named 'google.appengine'

During handling of the above exception, another exception occurred:

Traceback (most recent call last):
  File "C:\Users\scary\AppData\Local\Programs\Python\Python36\lib\site-packages\googleapiclient\discovery_cache\file_cache.py", line 33, in <module>
    from oauth2client.contrib.locked_file import LockedFile
ModuleNotFoundError: No module named 'oauth2client'

During handling of the above exception, another exception occurred:

Traceback (most recent call last):
  File "C:\Users\scary\AppData\Local\Programs\Python\Python36\lib\site-packages\googleapiclient\discovery_cache\file_cache.py", line 37, in <module>
    from oauth2client.locked_file import LockedFile
ModuleNotFoundError: No module named 'oauth2client'

During handling of the above exception, another exception occurred:

Traceback (most recent call last):
  File "C:\Users\scary\AppData\Local\Programs\Python\Python36\lib\site-packages\googleapiclient\discovery_cache\__init__.py", line 41, in autodetect
    from . import file_cache
  File "C:\Users\scary\AppData\Local\Programs\Python\Python36\lib\site-packages\googleapiclient\discovery_cache\file_cache.py", line 41, in <module>
    'file_cache is unavailable when using oauth2client >= 4.0.0 or google-auth')
ImportError: file_cache is unavailable when using oauth2client >= 4.0.0 or google-auth
INFO:googleapiclient.discovery:URL being requested: GET https://www.googleapis.com/discovery/v1/apis/sheets/v4/rest
INFO:root:Received |xp| command from |Scarybone|
INFO:root:Received |xp| command from |Scarybone|
INFO:discord.client:logging in using static token
INFO:discord.gateway:Created websocket connected to wss://gateway.discord.gg?encoding=json&v=6&compress=zlib-stream
INFO:discord.gateway:Shard ID None has sent the IDENTIFY payload.
INFO:discord.gateway:Shard ID None has connected to Gateway: gateway-prd-main-wnbm, discord-sessions-prd-1-14 (Session ID: 788a3afb2c144d503f2f6058e315eb38).
INFO:root:Logging in as:Party-Bot : 438288661398683650
INFO:discord.client:logging in using static token
INFO:discord.gateway:Created websocket connected to wss://gateway.discord.gg?encoding=json&v=6&compress=zlib-stream
INFO:discord.gateway:Shard ID None has sent the IDENTIFY payload.
INFO:discord.gateway:Shard ID None has connected to Gateway: gateway-prd-main-kqp0, discord-sessions-prd-1-8 (Session ID: 466e55602890154223251fb1aa146b3b).
INFO:root:Logging in as:Party-Bot : 438288661398683650
INFO:discord.client:logging in using static token
INFO:discord.gateway:Created websocket connected to wss://gateway.discord.gg?encoding=json&v=6&compress=zlib-stream
INFO:discord.gateway:Shard ID None has sent the IDENTIFY payload.
INFO:discord.gateway:Shard ID None has connected to Gateway: gateway-prd-main-8w26, discord-sessions-prd-1-12 (Session ID: b0884e5d206d3f42279d659b5a0acae5).
INFO:root:Logging in as:Party-Bot : 438288661398683650
INFO:discord.client:logging in using static token
INFO:discord.gateway:Created websocket connected to wss://gateway.discord.gg?encoding=json&v=6&compress=zlib-stream
INFO:discord.gateway:Shard ID None has sent the IDENTIFY payload.
INFO:discord.gateway:Shard ID None has connected to Gateway: gateway-prd-main-3r4t, discord-sessions-prd-1-20 (Session ID: b9103bf762e36f2a909886df14d109fb).
INFO:root:Logging in as:Party-Bot : 438288661398683650
WARNING:googleapiclient.discovery_cache:file_cache is unavailable when using oauth2client >= 4.0.0 or google-auth
Traceback (most recent call last):
  File "C:\Users\scary\AppData\Local\Programs\Python\Python36\lib\site-packages\googleapiclient\discovery_cache\__init__.py", line 36, in autodetect
    from google.appengine.api import memcache
ModuleNotFoundError: No module named 'google.appengine'

During handling of the above exception, another exception occurred:

Traceback (most recent call last):
  File "C:\Users\scary\AppData\Local\Programs\Python\Python36\lib\site-packages\googleapiclient\discovery_cache\file_cache.py", line 33, in <module>
    from oauth2client.contrib.locked_file import LockedFile
ModuleNotFoundError: No module named 'oauth2client'

During handling of the above exception, another exception occurred:

Traceback (most recent call last):
  File "C:\Users\scary\AppData\Local\Programs\Python\Python36\lib\site-packages\googleapiclient\discovery_cache\file_cache.py", line 37, in <module>
    from oauth2client.locked_file import LockedFile
ModuleNotFoundError: No module named 'oauth2client'

During handling of the above exception, another exception occurred:

Traceback (most recent call last):
  File "C:\Users\scary\AppData\Local\Programs\Python\Python36\lib\site-packages\googleapiclient\discovery_cache\__init__.py", line 41, in autodetect
    from . import file_cache
  File "C:\Users\scary\AppData\Local\Programs\Python\Python36\lib\site-packages\googleapiclient\discovery_cache\file_cache.py", line 41, in <module>
    'file_cache is unavailable when using oauth2client >= 4.0.0 or google-auth')
ImportError: file_cache is unavailable when using oauth2client >= 4.0.0 or google-auth
INFO:googleapiclient.discovery:URL being requested: GET https://www.googleapis.com/discovery/v1/apis/sheets/v4/rest
INFO:discord.client:logging in using static token
INFO:discord.gateway:Created websocket connected to wss://gateway.discord.gg?encoding=json&v=6&compress=zlib-stream
INFO:discord.gateway:Shard ID None has sent the IDENTIFY payload.
INFO:discord.gateway:Shard ID None has connected to Gateway: gateway-prd-main-tn9l, discord-sessions-prd-1-4 (Session ID: 2a931c325b84ab30ab791a15df84dac8).
INFO:root:Logging in as:Party-Bot : 438288661398683650
WARNING:googleapiclient.discovery_cache:file_cache is unavailable when using oauth2client >= 4.0.0 or google-auth
Traceback (most recent call last):
  File "C:\Users\scary\AppData\Local\Programs\Python\Python36\lib\site-packages\googleapiclient\discovery_cache\__init__.py", line 36, in autodetect
    from google.appengine.api import memcache
ModuleNotFoundError: No module named 'google.appengine'

During handling of the above exception, another exception occurred:

Traceback (most recent call last):
  File "C:\Users\scary\AppData\Local\Programs\Python\Python36\lib\site-packages\googleapiclient\discovery_cache\file_cache.py", line 33, in <module>
    from oauth2client.contrib.locked_file import LockedFile
ModuleNotFoundError: No module named 'oauth2client'

During handling of the above exception, another exception occurred:

Traceback (most recent call last):
  File "C:\Users\scary\AppData\Local\Programs\Python\Python36\lib\site-packages\googleapiclient\discovery_cache\file_cache.py", line 37, in <module>
    from oauth2client.locked_file import LockedFile
ModuleNotFoundError: No module named 'oauth2client'

During handling of the above exception, another exception occurred:

Traceback (most recent call last):
  File "C:\Users\scary\AppData\Local\Programs\Python\Python36\lib\site-packages\googleapiclient\discovery_cache\__init__.py", line 41, in autodetect
    from . import file_cache
  File "C:\Users\scary\AppData\Local\Programs\Python\Python36\lib\site-packages\googleapiclient\discovery_cache\file_cache.py", line 41, in <module>
    'file_cache is unavailable when using oauth2client >= 4.0.0 or google-auth')
ImportError: file_cache is unavailable when using oauth2client >= 4.0.0 or google-auth
INFO:googleapiclient.discovery:URL being requested: GET https://www.googleapis.com/discovery/v1/apis/sheets/v4/rest
INFO:googleapiclient.discovery:URL being requested: GET https://sheets.googleapis.com/v4/spreadsheets/1dVZlsgtbUq0MGWV4kBg7m6Kwv2kQtbBd88KFHq9uumo/values/Character%20Chart%21A2%3AG13?alt=json
INFO:root:Received |xp| command from |Scarybone|
INFO:discord.client:logging in using static token
INFO:discord.gateway:Created websocket connected to wss://gateway.discord.gg?encoding=json&v=6&compress=zlib-stream
INFO:discord.gateway:Shard ID None has sent the IDENTIFY payload.
INFO:discord.gateway:Shard ID None has connected to Gateway: gateway-prd-main-zml2, discord-sessions-prd-1-23 (Session ID: 4c26188620596004ee45ad9da2cf2a42).
INFO:root:Logging in as:Party-Bot : 438288661398683650
WARNING:googleapiclient.discovery_cache:file_cache is unavailable when using oauth2client >= 4.0.0 or google-auth
Traceback (most recent call last):
  File "C:\Users\scary\AppData\Local\Programs\Python\Python36\lib\site-packages\googleapiclient\discovery_cache\__init__.py", line 36, in autodetect
    from google.appengine.api import memcache
ModuleNotFoundError: No module named 'google.appengine'

During handling of the above exception, another exception occurred:

Traceback (most recent call last):
  File "C:\Users\scary\AppData\Local\Programs\Python\Python36\lib\site-packages\googleapiclient\discovery_cache\file_cache.py", line 33, in <module>
    from oauth2client.contrib.locked_file import LockedFile
ModuleNotFoundError: No module named 'oauth2client'

During handling of the above exception, another exception occurred:

Traceback (most recent call last):
  File "C:\Users\scary\AppData\Local\Programs\Python\Python36\lib\site-packages\googleapiclient\discovery_cache\file_cache.py", line 37, in <module>
    from oauth2client.locked_file import LockedFile
ModuleNotFoundError: No module named 'oauth2client'

During handling of the above exception, another exception occurred:

Traceback (most recent call last):
  File "C:\Users\scary\AppData\Local\Programs\Python\Python36\lib\site-packages\googleapiclient\discovery_cache\__init__.py", line 41, in autodetect
    from . import file_cache
  File "C:\Users\scary\AppData\Local\Programs\Python\Python36\lib\site-packages\googleapiclient\discovery_cache\file_cache.py", line 41, in <module>
    'file_cache is unavailable when using oauth2client >= 4.0.0 or google-auth')
ImportError: file_cache is unavailable when using oauth2client >= 4.0.0 or google-auth
INFO:googleapiclient.discovery:URL being requested: GET https://www.googleapis.com/discovery/v1/apis/sheets/v4/rest
INFO:googleapiclient.discovery:URL being requested: GET https://sheets.googleapis.com/v4/spreadsheets/1dVZlsgtbUq0MGWV4kBg7m6Kwv2kQtbBd88KFHq9uumo/values/Character%20Chart%21A2%3AG13?alt=json
INFO:root:Received |xp| command from |Scarybone|
INFO:discord.client:logging in using static token
INFO:discord.gateway:Created websocket connected to wss://gateway.discord.gg?encoding=json&v=6&compress=zlib-stream
INFO:discord.gateway:Shard ID None has sent the IDENTIFY payload.
INFO:discord.gateway:Shard ID None has connected to Gateway: gateway-prd-main-lsm2, discord-sessions-prd-1-28 (Session ID: 1e2064dab8282f288f4501cc4cdfc08f).
INFO:root:Logging in as:Party-Bot : 438288661398683650
WARNING:googleapiclient.discovery_cache:file_cache is unavailable when using oauth2client >= 4.0.0 or google-auth
Traceback (most recent call last):
  File "C:\Users\scary\AppData\Local\Programs\Python\Python36\lib\site-packages\googleapiclient\discovery_cache\__init__.py", line 36, in autodetect
    from google.appengine.api import memcache
ModuleNotFoundError: No module named 'google.appengine'

During handling of the above exception, another exception occurred:

Traceback (most recent call last):
  File "C:\Users\scary\AppData\Local\Programs\Python\Python36\lib\site-packages\googleapiclient\discovery_cache\file_cache.py", line 33, in <module>
    from oauth2client.contrib.locked_file import LockedFile
ModuleNotFoundError: No module named 'oauth2client'

During handling of the above exception, another exception occurred:

Traceback (most recent call last):
  File "C:\Users\scary\AppData\Local\Programs\Python\Python36\lib\site-packages\googleapiclient\discovery_cache\file_cache.py", line 37, in <module>
    from oauth2client.locked_file import LockedFile
ModuleNotFoundError: No module named 'oauth2client'

During handling of the above exception, another exception occurred:

Traceback (most recent call last):
  File "C:\Users\scary\AppData\Local\Programs\Python\Python36\lib\site-packages\googleapiclient\discovery_cache\__init__.py", line 41, in autodetect
    from . import file_cache
  File "C:\Users\scary\AppData\Local\Programs\Python\Python36\lib\site-packages\googleapiclient\discovery_cache\file_cache.py", line 41, in <module>
    'file_cache is unavailable when using oauth2client >= 4.0.0 or google-auth')
ImportError: file_cache is unavailable when using oauth2client >= 4.0.0 or google-auth
INFO:googleapiclient.discovery:URL being requested: GET https://www.googleapis.com/discovery/v1/apis/sheets/v4/rest
INFO:root:Received |current| command from |Scarybone|
INFO:root:Received |bank| command from |Scarybone|
WARNING:discord.gateway:Can't keep up, websocket is 11.0s behind.
INFO:discord.client:logging in using static token
INFO:discord.gateway:Created websocket connected to wss://gateway.discord.gg?encoding=json&v=6&compress=zlib-stream
INFO:discord.gateway:Shard ID None has sent the IDENTIFY payload.
INFO:discord.gateway:Shard ID None has connected to Gateway: gateway-prd-main-74l8, discord-sessions-prd-1-9 (Session ID: 9b4568cf55110502c6a22e66efffb88a).
INFO:root:Logging in as:Party-Bot : 438288661398683650
WARNING:googleapiclient.discovery_cache:file_cache is unavailable when using oauth2client >= 4.0.0 or google-auth
Traceback (most recent call last):
  File "C:\Users\scary\AppData\Local\Programs\Python\Python36\lib\site-packages\googleapiclient\discovery_cache\__init__.py", line 36, in autodetect
    from google.appengine.api import memcache
ModuleNotFoundError: No module named 'google.appengine'

During handling of the above exception, another exception occurred:

Traceback (most recent call last):
  File "C:\Users\scary\AppData\Local\Programs\Python\Python36\lib\site-packages\googleapiclient\discovery_cache\file_cache.py", line 33, in <module>
    from oauth2client.contrib.locked_file import LockedFile
ModuleNotFoundError: No module named 'oauth2client'

During handling of the above exception, another exception occurred:

Traceback (most recent call last):
  File "C:\Users\scary\AppData\Local\Programs\Python\Python36\lib\site-packages\googleapiclient\discovery_cache\file_cache.py", line 37, in <module>
    from oauth2client.locked_file import LockedFile
ModuleNotFoundError: No module named 'oauth2client'

During handling of the above exception, another exception occurred:

Traceback (most recent call last):
  File "C:\Users\scary\AppData\Local\Programs\Python\Python36\lib\site-packages\googleapiclient\discovery_cache\__init__.py", line 41, in autodetect
    from . import file_cache
  File "C:\Users\scary\AppData\Local\Programs\Python\Python36\lib\site-packages\googleapiclient\discovery_cache\file_cache.py", line 41, in <module>
    'file_cache is unavailable when using oauth2client >= 4.0.0 or google-auth')
ImportError: file_cache is unavailable when using oauth2client >= 4.0.0 or google-auth
INFO:googleapiclient.discovery:URL being requested: GET https://www.googleapis.com/discovery/v1/apis/sheets/v4/rest
WARNING:discord.gateway:Unknown event PRESENCES_REPLACE.
INFO:googleapiclient.discovery:URL being requested: GET https://sheets.googleapis.com/v4/spreadsheets/1dVZlsgtbUq0MGWV4kBg7m6Kwv2kQtbBd88KFHq9uumo/values/Character%20Chart%21A%3AG?alt=json
INFO:root:Received |current| command from |Scarybone|
WARNING:discord.gateway:Can't keep up, websocket is 24.3s behind.
INFO:googleapiclient.discovery:URL being requested: GET https://sheets.googleapis.com/v4/spreadsheets/1dVZlsgtbUq0MGWV4kBg7m6Kwv2kQtbBd88KFHq9uumo/values/Character%20Chart%21A%3AG?alt=json
INFO:root:Received |current| command from |Scarybone|
INFO:discord.client:logging in using static token
INFO:discord.gateway:Created websocket connected to wss://gateway.discord.gg?encoding=json&v=6&compress=zlib-stream
INFO:discord.gateway:Shard ID None has sent the IDENTIFY payload.
INFO:discord.gateway:Shard ID None has connected to Gateway: gateway-prd-main-8w26, discord-sessions-prd-1-29 (Session ID: 60f3d82d8bb56bee4edb5fbb762a0229).
INFO:root:Logging in as:Party-Bot : 438288661398683650
WARNING:googleapiclient.discovery_cache:file_cache is unavailable when using oauth2client >= 4.0.0 or google-auth
Traceback (most recent call last):
  File "C:\Users\scary\AppData\Local\Programs\Python\Python36\lib\site-packages\googleapiclient\discovery_cache\__init__.py", line 36, in autodetect
    from google.appengine.api import memcache
ModuleNotFoundError: No module named 'google.appengine'

During handling of the above exception, another exception occurred:

Traceback (most recent call last):
  File "C:\Users\scary\AppData\Local\Programs\Python\Python36\lib\site-packages\googleapiclient\discovery_cache\file_cache.py", line 33, in <module>
    from oauth2client.contrib.locked_file import LockedFile
ModuleNotFoundError: No module named 'oauth2client'

During handling of the above exception, another exception occurred:

Traceback (most recent call last):
  File "C:\Users\scary\AppData\Local\Programs\Python\Python36\lib\site-packages\googleapiclient\discovery_cache\file_cache.py", line 37, in <module>
    from oauth2client.locked_file import LockedFile
ModuleNotFoundError: No module named 'oauth2client'

During handling of the above exception, another exception occurred:

Traceback (most recent call last):
  File "C:\Users\scary\AppData\Local\Programs\Python\Python36\lib\site-packages\googleapiclient\discovery_cache\__init__.py", line 41, in autodetect
    from . import file_cache
  File "C:\Users\scary\AppData\Local\Programs\Python\Python36\lib\site-packages\googleapiclient\discovery_cache\file_cache.py", line 41, in <module>
    'file_cache is unavailable when using oauth2client >= 4.0.0 or google-auth')
ImportError: file_cache is unavailable when using oauth2client >= 4.0.0 or google-auth
INFO:googleapiclient.discovery:URL being requested: GET https://www.googleapis.com/discovery/v1/apis/sheets/v4/rest
INFO:googleapiclient.discovery:URL being requested: GET https://sheets.googleapis.com/v4/spreadsheets/1dVZlsgtbUq0MGWV4kBg7m6Kwv2kQtbBd88KFHq9uumo/values/Bank%20Chart%21A%3AC?alt=json
INFO:root:Received |bank| command from |Scarybone|
INFO:discord.gateway:Websocket closed with 1006 (), attempting a reconnect.
INFO:discord.client:Got a request to RESUME the websocket.
ERROR:discord.client:Attempting a reconnect in 0.96s
Traceback (most recent call last):
  File "C:\Users\scary\AppData\Local\Programs\Python\Python36\lib\site-packages\aiohttp\connector.py", line 955, in _create_direct_connection
    traces=traces), loop=self._loop)
  File "C:\Users\scary\AppData\Local\Programs\Python\Python36\lib\site-packages\aiohttp\connector.py", line 825, in _resolve_host
    self._resolver.resolve(host, port, family=self._family)
  File "C:\Users\scary\AppData\Local\Programs\Python\Python36\lib\site-packages\aiohttp\resolver.py", line 30, in resolve
    host, port, type=socket.SOCK_STREAM, family=family)
  File "C:\Users\scary\AppData\Local\Programs\Python\Python36\lib\concurrent\futures\thread.py", line 56, in run
    result = self.fn(*self.args, **self.kwargs)
  File "C:\Users\scary\AppData\Local\Programs\Python\Python36\lib\socket.py", line 745, in getaddrinfo
    for res in _socket.getaddrinfo(host, port, family, type, proto, flags):
socket.gaierror: [Errno 11001] getaddrinfo failed

The above exception was the direct cause of the following exception:

Traceback (most recent call last):
  File "C:\Users\scary\AppData\Local\Programs\Python\Python36\lib\site-packages\discord\client.py", line 442, in connect
    await self._connect()
  File "C:\Users\scary\AppData\Local\Programs\Python\Python36\lib\site-packages\discord\client.py", line 412, in _connect
    self.ws = await asyncio.wait_for(coro, timeout=180.0, loop=self.loop)
  File "C:\Users\scary\AppData\Local\Programs\Python\Python36\lib\asyncio\tasks.py", line 358, in wait_for
    return fut.result()
  File "C:\Users\scary\AppData\Local\Programs\Python\Python36\lib\site-packages\discord\gateway.py", line 224, in from_client
    gateway = await client.http.get_gateway()
  File "C:\Users\scary\AppData\Local\Programs\Python\Python36\lib\site-packages\discord\http.py", line 788, in get_gateway
    data = await self.request(Route('GET', '/gateway'))
  File "C:\Users\scary\AppData\Local\Programs\Python\Python36\lib\site-packages\discord\http.py", line 158, in request
    async with self.__session.request(method, url, **kwargs) as r:
  File "C:\Users\scary\AppData\Local\Programs\Python\Python36\lib\site-packages\aiohttp\client.py", line 1005, in __aenter__
    self._resp = await self._coro
  File "C:\Users\scary\AppData\Local\Programs\Python\Python36\lib\site-packages\aiohttp\client.py", line 476, in _request
    timeout=real_timeout
  File "C:\Users\scary\AppData\Local\Programs\Python\Python36\lib\site-packages\aiohttp\connector.py", line 522, in connect
    proto = await self._create_connection(req, traces, timeout)
  File "C:\Users\scary\AppData\Local\Programs\Python\Python36\lib\site-packages\aiohttp\connector.py", line 854, in _create_connection
    req, traces, timeout)
  File "C:\Users\scary\AppData\Local\Programs\Python\Python36\lib\site-packages\aiohttp\connector.py", line 959, in _create_direct_connection
    raise ClientConnectorError(req.connection_key, exc) from exc
aiohttp.client_exceptions.ClientConnectorError: Cannot connect to host discordapp.com:443 ssl:None [getaddrinfo failed]
ERROR:discord.client:Attempting a reconnect in 3.25s
Traceback (most recent call last):
  File "C:\Users\scary\AppData\Local\Programs\Python\Python36\lib\site-packages\aiohttp\connector.py", line 955, in _create_direct_connection
    traces=traces), loop=self._loop)
  File "C:\Users\scary\AppData\Local\Programs\Python\Python36\lib\site-packages\aiohttp\connector.py", line 825, in _resolve_host
    self._resolver.resolve(host, port, family=self._family)
  File "C:\Users\scary\AppData\Local\Programs\Python\Python36\lib\site-packages\aiohttp\resolver.py", line 30, in resolve
    host, port, type=socket.SOCK_STREAM, family=family)
  File "C:\Users\scary\AppData\Local\Programs\Python\Python36\lib\concurrent\futures\thread.py", line 56, in run
    result = self.fn(*self.args, **self.kwargs)
  File "C:\Users\scary\AppData\Local\Programs\Python\Python36\lib\socket.py", line 745, in getaddrinfo
    for res in _socket.getaddrinfo(host, port, family, type, proto, flags):
socket.gaierror: [Errno 11001] getaddrinfo failed

The above exception was the direct cause of the following exception:

Traceback (most recent call last):
  File "C:\Users\scary\AppData\Local\Programs\Python\Python36\lib\site-packages\discord\client.py", line 442, in connect
    await self._connect()
  File "C:\Users\scary\AppData\Local\Programs\Python\Python36\lib\site-packages\discord\client.py", line 403, in _connect
    self.ws = await asyncio.wait_for(coro, timeout=180.0, loop=self.loop)
  File "C:\Users\scary\AppData\Local\Programs\Python\Python36\lib\asyncio\tasks.py", line 358, in wait_for
    return fut.result()
  File "C:\Users\scary\AppData\Local\Programs\Python\Python36\lib\site-packages\discord\gateway.py", line 224, in from_client
    gateway = await client.http.get_gateway()
  File "C:\Users\scary\AppData\Local\Programs\Python\Python36\lib\site-packages\discord\http.py", line 788, in get_gateway
    data = await self.request(Route('GET', '/gateway'))
  File "C:\Users\scary\AppData\Local\Programs\Python\Python36\lib\site-packages\discord\http.py", line 158, in request
    async with self.__session.request(method, url, **kwargs) as r:
  File "C:\Users\scary\AppData\Local\Programs\Python\Python36\lib\site-packages\aiohttp\client.py", line 1005, in __aenter__
    self._resp = await self._coro
  File "C:\Users\scary\AppData\Local\Programs\Python\Python36\lib\site-packages\aiohttp\client.py", line 476, in _request
    timeout=real_timeout
  File "C:\Users\scary\AppData\Local\Programs\Python\Python36\lib\site-packages\aiohttp\connector.py", line 522, in connect
    proto = await self._create_connection(req, traces, timeout)
  File "C:\Users\scary\AppData\Local\Programs\Python\Python36\lib\site-packages\aiohttp\connector.py", line 854, in _create_connection
    req, traces, timeout)
  File "C:\Users\scary\AppData\Local\Programs\Python\Python36\lib\site-packages\aiohttp\connector.py", line 959, in _create_direct_connection
    raise ClientConnectorError(req.connection_key, exc) from exc
aiohttp.client_exceptions.ClientConnectorError: Cannot connect to host discordapp.com:443 ssl:None [getaddrinfo failed]
ERROR:discord.client:Attempting a reconnect in 2.77s
Traceback (most recent call last):
  File "C:\Users\scary\AppData\Local\Programs\Python\Python36\lib\site-packages\aiohttp\connector.py", line 955, in _create_direct_connection
    traces=traces), loop=self._loop)
  File "C:\Users\scary\AppData\Local\Programs\Python\Python36\lib\site-packages\aiohttp\connector.py", line 825, in _resolve_host
    self._resolver.resolve(host, port, family=self._family)
  File "C:\Users\scary\AppData\Local\Programs\Python\Python36\lib\site-packages\aiohttp\resolver.py", line 30, in resolve
    host, port, type=socket.SOCK_STREAM, family=family)
  File "C:\Users\scary\AppData\Local\Programs\Python\Python36\lib\concurrent\futures\thread.py", line 56, in run
    result = self.fn(*self.args, **self.kwargs)
  File "C:\Users\scary\AppData\Local\Programs\Python\Python36\lib\socket.py", line 745, in getaddrinfo
    for res in _socket.getaddrinfo(host, port, family, type, proto, flags):
socket.gaierror: [Errno 11001] getaddrinfo failed

The above exception was the direct cause of the following exception:

Traceback (most recent call last):
  File "C:\Users\scary\AppData\Local\Programs\Python\Python36\lib\site-packages\discord\client.py", line 442, in connect
    await self._connect()
  File "C:\Users\scary\AppData\Local\Programs\Python\Python36\lib\site-packages\discord\client.py", line 403, in _connect
    self.ws = await asyncio.wait_for(coro, timeout=180.0, loop=self.loop)
  File "C:\Users\scary\AppData\Local\Programs\Python\Python36\lib\asyncio\tasks.py", line 358, in wait_for
    return fut.result()
  File "C:\Users\scary\AppData\Local\Programs\Python\Python36\lib\site-packages\discord\gateway.py", line 224, in from_client
    gateway = await client.http.get_gateway()
  File "C:\Users\scary\AppData\Local\Programs\Python\Python36\lib\site-packages\discord\http.py", line 788, in get_gateway
    data = await self.request(Route('GET', '/gateway'))
  File "C:\Users\scary\AppData\Local\Programs\Python\Python36\lib\site-packages\discord\http.py", line 158, in request
    async with self.__session.request(method, url, **kwargs) as r:
  File "C:\Users\scary\AppData\Local\Programs\Python\Python36\lib\site-packages\aiohttp\client.py", line 1005, in __aenter__
    self._resp = await self._coro
  File "C:\Users\scary\AppData\Local\Programs\Python\Python36\lib\site-packages\aiohttp\client.py", line 476, in _request
    timeout=real_timeout
  File "C:\Users\scary\AppData\Local\Programs\Python\Python36\lib\site-packages\aiohttp\connector.py", line 522, in connect
    proto = await self._create_connection(req, traces, timeout)
  File "C:\Users\scary\AppData\Local\Programs\Python\Python36\lib\site-packages\aiohttp\connector.py", line 854, in _create_connection
    req, traces, timeout)
  File "C:\Users\scary\AppData\Local\Programs\Python\Python36\lib\site-packages\aiohttp\connector.py", line 959, in _create_direct_connection
    raise ClientConnectorError(req.connection_key, exc) from exc
aiohttp.client_exceptions.ClientConnectorError: Cannot connect to host discordapp.com:443 ssl:None [getaddrinfo failed]
ERROR:discord.client:Attempting a reconnect in 0.40s
Traceback (most recent call last):
  File "C:\Users\scary\AppData\Local\Programs\Python\Python36\lib\site-packages\aiohttp\connector.py", line 955, in _create_direct_connection
    traces=traces), loop=self._loop)
  File "C:\Users\scary\AppData\Local\Programs\Python\Python36\lib\site-packages\aiohttp\connector.py", line 825, in _resolve_host
    self._resolver.resolve(host, port, family=self._family)
  File "C:\Users\scary\AppData\Local\Programs\Python\Python36\lib\site-packages\aiohttp\resolver.py", line 30, in resolve
    host, port, type=socket.SOCK_STREAM, family=family)
  File "C:\Users\scary\AppData\Local\Programs\Python\Python36\lib\concurrent\futures\thread.py", line 56, in run
    result = self.fn(*self.args, **self.kwargs)
  File "C:\Users\scary\AppData\Local\Programs\Python\Python36\lib\socket.py", line 745, in getaddrinfo
    for res in _socket.getaddrinfo(host, port, family, type, proto, flags):
socket.gaierror: [Errno 11001] getaddrinfo failed

The above exception was the direct cause of the following exception:

Traceback (most recent call last):
  File "C:\Users\scary\AppData\Local\Programs\Python\Python36\lib\site-packages\discord\client.py", line 442, in connect
    await self._connect()
  File "C:\Users\scary\AppData\Local\Programs\Python\Python36\lib\site-packages\discord\client.py", line 403, in _connect
    self.ws = await asyncio.wait_for(coro, timeout=180.0, loop=self.loop)
  File "C:\Users\scary\AppData\Local\Programs\Python\Python36\lib\asyncio\tasks.py", line 358, in wait_for
    return fut.result()
  File "C:\Users\scary\AppData\Local\Programs\Python\Python36\lib\site-packages\discord\gateway.py", line 224, in from_client
    gateway = await client.http.get_gateway()
  File "C:\Users\scary\AppData\Local\Programs\Python\Python36\lib\site-packages\discord\http.py", line 788, in get_gateway
    data = await self.request(Route('GET', '/gateway'))
  File "C:\Users\scary\AppData\Local\Programs\Python\Python36\lib\site-packages\discord\http.py", line 158, in request
    async with self.__session.request(method, url, **kwargs) as r:
  File "C:\Users\scary\AppData\Local\Programs\Python\Python36\lib\site-packages\aiohttp\client.py", line 1005, in __aenter__
    self._resp = await self._coro
  File "C:\Users\scary\AppData\Local\Programs\Python\Python36\lib\site-packages\aiohttp\client.py", line 476, in _request
    timeout=real_timeout
  File "C:\Users\scary\AppData\Local\Programs\Python\Python36\lib\site-packages\aiohttp\connector.py", line 522, in connect
    proto = await self._create_connection(req, traces, timeout)
  File "C:\Users\scary\AppData\Local\Programs\Python\Python36\lib\site-packages\aiohttp\connector.py", line 854, in _create_connection
    req, traces, timeout)
  File "C:\Users\scary\AppData\Local\Programs\Python\Python36\lib\site-packages\aiohttp\connector.py", line 959, in _create_direct_connection
    raise ClientConnectorError(req.connection_key, exc) from exc
aiohttp.client_exceptions.ClientConnectorError: Cannot connect to host discordapp.com:443 ssl:None [getaddrinfo failed]
ERROR:discord.client:Attempting a reconnect in 2.98s
Traceback (most recent call last):
  File "C:\Users\scary\AppData\Local\Programs\Python\Python36\lib\site-packages\aiohttp\connector.py", line 955, in _create_direct_connection
    traces=traces), loop=self._loop)
  File "C:\Users\scary\AppData\Local\Programs\Python\Python36\lib\site-packages\aiohttp\connector.py", line 825, in _resolve_host
    self._resolver.resolve(host, port, family=self._family)
  File "C:\Users\scary\AppData\Local\Programs\Python\Python36\lib\site-packages\aiohttp\resolver.py", line 30, in resolve
    host, port, type=socket.SOCK_STREAM, family=family)
  File "C:\Users\scary\AppData\Local\Programs\Python\Python36\lib\concurrent\futures\thread.py", line 56, in run
    result = self.fn(*self.args, **self.kwargs)
  File "C:\Users\scary\AppData\Local\Programs\Python\Python36\lib\socket.py", line 745, in getaddrinfo
    for res in _socket.getaddrinfo(host, port, family, type, proto, flags):
socket.gaierror: [Errno 11001] getaddrinfo failed

The above exception was the direct cause of the following exception:

Traceback (most recent call last):
  File "C:\Users\scary\AppData\Local\Programs\Python\Python36\lib\site-packages\discord\client.py", line 442, in connect
    await self._connect()
  File "C:\Users\scary\AppData\Local\Programs\Python\Python36\lib\site-packages\discord\client.py", line 403, in _connect
    self.ws = await asyncio.wait_for(coro, timeout=180.0, loop=self.loop)
  File "C:\Users\scary\AppData\Local\Programs\Python\Python36\lib\asyncio\tasks.py", line 358, in wait_for
    return fut.result()
  File "C:\Users\scary\AppData\Local\Programs\Python\Python36\lib\site-packages\discord\gateway.py", line 224, in from_client
    gateway = await client.http.get_gateway()
  File "C:\Users\scary\AppData\Local\Programs\Python\Python36\lib\site-packages\discord\http.py", line 788, in get_gateway
    data = await self.request(Route('GET', '/gateway'))
  File "C:\Users\scary\AppData\Local\Programs\Python\Python36\lib\site-packages\discord\http.py", line 158, in request
    async with self.__session.request(method, url, **kwargs) as r:
  File "C:\Users\scary\AppData\Local\Programs\Python\Python36\lib\site-packages\aiohttp\client.py", line 1005, in __aenter__
    self._resp = await self._coro
  File "C:\Users\scary\AppData\Local\Programs\Python\Python36\lib\site-packages\aiohttp\client.py", line 476, in _request
    timeout=real_timeout
  File "C:\Users\scary\AppData\Local\Programs\Python\Python36\lib\site-packages\aiohttp\connector.py", line 522, in connect
    proto = await self._create_connection(req, traces, timeout)
  File "C:\Users\scary\AppData\Local\Programs\Python\Python36\lib\site-packages\aiohttp\connector.py", line 854, in _create_connection
    req, traces, timeout)
  File "C:\Users\scary\AppData\Local\Programs\Python\Python36\lib\site-packages\aiohttp\connector.py", line 959, in _create_direct_connection
    raise ClientConnectorError(req.connection_key, exc) from exc
aiohttp.client_exceptions.ClientConnectorError: Cannot connect to host discordapp.com:443 ssl:None [getaddrinfo failed]
ERROR:discord.client:Attempting a reconnect in 2.90s
Traceback (most recent call last):
  File "C:\Users\scary\AppData\Local\Programs\Python\Python36\lib\site-packages\aiohttp\connector.py", line 955, in _create_direct_connection
    traces=traces), loop=self._loop)
  File "C:\Users\scary\AppData\Local\Programs\Python\Python36\lib\site-packages\aiohttp\connector.py", line 825, in _resolve_host
    self._resolver.resolve(host, port, family=self._family)
  File "C:\Users\scary\AppData\Local\Programs\Python\Python36\lib\site-packages\aiohttp\resolver.py", line 30, in resolve
    host, port, type=socket.SOCK_STREAM, family=family)
  File "C:\Users\scary\AppData\Local\Programs\Python\Python36\lib\concurrent\futures\thread.py", line 56, in run
    result = self.fn(*self.args, **self.kwargs)
  File "C:\Users\scary\AppData\Local\Programs\Python\Python36\lib\socket.py", line 745, in getaddrinfo
    for res in _socket.getaddrinfo(host, port, family, type, proto, flags):
socket.gaierror: [Errno 11001] getaddrinfo failed

The above exception was the direct cause of the following exception:

Traceback (most recent call last):
  File "C:\Users\scary\AppData\Local\Programs\Python\Python36\lib\site-packages\discord\client.py", line 442, in connect
    await self._connect()
  File "C:\Users\scary\AppData\Local\Programs\Python\Python36\lib\site-packages\discord\client.py", line 403, in _connect
    self.ws = await asyncio.wait_for(coro, timeout=180.0, loop=self.loop)
  File "C:\Users\scary\AppData\Local\Programs\Python\Python36\lib\asyncio\tasks.py", line 358, in wait_for
    return fut.result()
  File "C:\Users\scary\AppData\Local\Programs\Python\Python36\lib\site-packages\discord\gateway.py", line 224, in from_client
    gateway = await client.http.get_gateway()
  File "C:\Users\scary\AppData\Local\Programs\Python\Python36\lib\site-packages\discord\http.py", line 788, in get_gateway
    data = await self.request(Route('GET', '/gateway'))
  File "C:\Users\scary\AppData\Local\Programs\Python\Python36\lib\site-packages\discord\http.py", line 158, in request
    async with self.__session.request(method, url, **kwargs) as r:
  File "C:\Users\scary\AppData\Local\Programs\Python\Python36\lib\site-packages\aiohttp\client.py", line 1005, in __aenter__
    self._resp = await self._coro
  File "C:\Users\scary\AppData\Local\Programs\Python\Python36\lib\site-packages\aiohttp\client.py", line 476, in _request
    timeout=real_timeout
  File "C:\Users\scary\AppData\Local\Programs\Python\Python36\lib\site-packages\aiohttp\connector.py", line 522, in connect
    proto = await self._create_connection(req, traces, timeout)
  File "C:\Users\scary\AppData\Local\Programs\Python\Python36\lib\site-packages\aiohttp\connector.py", line 854, in _create_connection
    req, traces, timeout)
  File "C:\Users\scary\AppData\Local\Programs\Python\Python36\lib\site-packages\aiohttp\connector.py", line 959, in _create_direct_connection
    raise ClientConnectorError(req.connection_key, exc) from exc
aiohttp.client_exceptions.ClientConnectorError: Cannot connect to host discordapp.com:443 ssl:None [getaddrinfo failed]
ERROR:discord.client:Attempting a reconnect in 4.73s
Traceback (most recent call last):
  File "C:\Users\scary\AppData\Local\Programs\Python\Python36\lib\site-packages\aiohttp\connector.py", line 955, in _create_direct_connection
    traces=traces), loop=self._loop)
  File "C:\Users\scary\AppData\Local\Programs\Python\Python36\lib\site-packages\aiohttp\connector.py", line 825, in _resolve_host
    self._resolver.resolve(host, port, family=self._family)
  File "C:\Users\scary\AppData\Local\Programs\Python\Python36\lib\site-packages\aiohttp\resolver.py", line 30, in resolve
    host, port, type=socket.SOCK_STREAM, family=family)
  File "C:\Users\scary\AppData\Local\Programs\Python\Python36\lib\concurrent\futures\thread.py", line 56, in run
    result = self.fn(*self.args, **self.kwargs)
  File "C:\Users\scary\AppData\Local\Programs\Python\Python36\lib\socket.py", line 745, in getaddrinfo
    for res in _socket.getaddrinfo(host, port, family, type, proto, flags):
socket.gaierror: [Errno 11001] getaddrinfo failed

The above exception was the direct cause of the following exception:

Traceback (most recent call last):
  File "C:\Users\scary\AppData\Local\Programs\Python\Python36\lib\site-packages\discord\client.py", line 442, in connect
    await self._connect()
  File "C:\Users\scary\AppData\Local\Programs\Python\Python36\lib\site-packages\discord\client.py", line 403, in _connect
    self.ws = await asyncio.wait_for(coro, timeout=180.0, loop=self.loop)
  File "C:\Users\scary\AppData\Local\Programs\Python\Python36\lib\asyncio\tasks.py", line 358, in wait_for
    return fut.result()
  File "C:\Users\scary\AppData\Local\Programs\Python\Python36\lib\site-packages\discord\gateway.py", line 224, in from_client
    gateway = await client.http.get_gateway()
  File "C:\Users\scary\AppData\Local\Programs\Python\Python36\lib\site-packages\discord\http.py", line 788, in get_gateway
    data = await self.request(Route('GET', '/gateway'))
  File "C:\Users\scary\AppData\Local\Programs\Python\Python36\lib\site-packages\discord\http.py", line 158, in request
    async with self.__session.request(method, url, **kwargs) as r:
  File "C:\Users\scary\AppData\Local\Programs\Python\Python36\lib\site-packages\aiohttp\client.py", line 1005, in __aenter__
    self._resp = await self._coro
  File "C:\Users\scary\AppData\Local\Programs\Python\Python36\lib\site-packages\aiohttp\client.py", line 476, in _request
    timeout=real_timeout
  File "C:\Users\scary\AppData\Local\Programs\Python\Python36\lib\site-packages\aiohttp\connector.py", line 522, in connect
    proto = await self._create_connection(req, traces, timeout)
  File "C:\Users\scary\AppData\Local\Programs\Python\Python36\lib\site-packages\aiohttp\connector.py", line 854, in _create_connection
    req, traces, timeout)
  File "C:\Users\scary\AppData\Local\Programs\Python\Python36\lib\site-packages\aiohttp\connector.py", line 959, in _create_direct_connection
    raise ClientConnectorError(req.connection_key, exc) from exc
aiohttp.client_exceptions.ClientConnectorError: Cannot connect to host discordapp.com:443 ssl:None [getaddrinfo failed]
ERROR:discord.client:Attempting a reconnect in 18.73s
Traceback (most recent call last):
  File "C:\Users\scary\AppData\Local\Programs\Python\Python36\lib\site-packages\aiohttp\connector.py", line 955, in _create_direct_connection
    traces=traces), loop=self._loop)
  File "C:\Users\scary\AppData\Local\Programs\Python\Python36\lib\site-packages\aiohttp\connector.py", line 825, in _resolve_host
    self._resolver.resolve(host, port, family=self._family)
  File "C:\Users\scary\AppData\Local\Programs\Python\Python36\lib\site-packages\aiohttp\resolver.py", line 30, in resolve
    host, port, type=socket.SOCK_STREAM, family=family)
  File "C:\Users\scary\AppData\Local\Programs\Python\Python36\lib\concurrent\futures\thread.py", line 56, in run
    result = self.fn(*self.args, **self.kwargs)
  File "C:\Users\scary\AppData\Local\Programs\Python\Python36\lib\socket.py", line 745, in getaddrinfo
    for res in _socket.getaddrinfo(host, port, family, type, proto, flags):
socket.gaierror: [Errno 11001] getaddrinfo failed

The above exception was the direct cause of the following exception:

Traceback (most recent call last):
  File "C:\Users\scary\AppData\Local\Programs\Python\Python36\lib\site-packages\discord\client.py", line 442, in connect
    await self._connect()
  File "C:\Users\scary\AppData\Local\Programs\Python\Python36\lib\site-packages\discord\client.py", line 403, in _connect
    self.ws = await asyncio.wait_for(coro, timeout=180.0, loop=self.loop)
  File "C:\Users\scary\AppData\Local\Programs\Python\Python36\lib\asyncio\tasks.py", line 358, in wait_for
    return fut.result()
  File "C:\Users\scary\AppData\Local\Programs\Python\Python36\lib\site-packages\discord\gateway.py", line 224, in from_client
    gateway = await client.http.get_gateway()
  File "C:\Users\scary\AppData\Local\Programs\Python\Python36\lib\site-packages\discord\http.py", line 788, in get_gateway
    data = await self.request(Route('GET', '/gateway'))
  File "C:\Users\scary\AppData\Local\Programs\Python\Python36\lib\site-packages\discord\http.py", line 158, in request
    async with self.__session.request(method, url, **kwargs) as r:
  File "C:\Users\scary\AppData\Local\Programs\Python\Python36\lib\site-packages\aiohttp\client.py", line 1005, in __aenter__
    self._resp = await self._coro
  File "C:\Users\scary\AppData\Local\Programs\Python\Python36\lib\site-packages\aiohttp\client.py", line 476, in _request
    timeout=real_timeout
  File "C:\Users\scary\AppData\Local\Programs\Python\Python36\lib\site-packages\aiohttp\connector.py", line 522, in connect
    proto = await self._create_connection(req, traces, timeout)
  File "C:\Users\scary\AppData\Local\Programs\Python\Python36\lib\site-packages\aiohttp\connector.py", line 854, in _create_connection
    req, traces, timeout)
  File "C:\Users\scary\AppData\Local\Programs\Python\Python36\lib\site-packages\aiohttp\connector.py", line 959, in _create_direct_connection
    raise ClientConnectorError(req.connection_key, exc) from exc
aiohttp.client_exceptions.ClientConnectorError: Cannot connect to host discordapp.com:443 ssl:None [getaddrinfo failed]
WARNING:discord.gateway:Shard ID None has stopped responding to the gateway. Closing and restarting.
ERROR:discord.client:Attempting a reconnect in 52.29s
Traceback (most recent call last):
  File "C:\Users\scary\AppData\Local\Programs\Python\Python36\lib\site-packages\aiohttp\connector.py", line 955, in _create_direct_connection
    traces=traces), loop=self._loop)
  File "C:\Users\scary\AppData\Local\Programs\Python\Python36\lib\site-packages\aiohttp\connector.py", line 825, in _resolve_host
    self._resolver.resolve(host, port, family=self._family)
  File "C:\Users\scary\AppData\Local\Programs\Python\Python36\lib\site-packages\aiohttp\resolver.py", line 30, in resolve
    host, port, type=socket.SOCK_STREAM, family=family)
  File "C:\Users\scary\AppData\Local\Programs\Python\Python36\lib\concurrent\futures\thread.py", line 56, in run
    result = self.fn(*self.args, **self.kwargs)
  File "C:\Users\scary\AppData\Local\Programs\Python\Python36\lib\socket.py", line 745, in getaddrinfo
    for res in _socket.getaddrinfo(host, port, family, type, proto, flags):
socket.gaierror: [Errno 11001] getaddrinfo failed

The above exception was the direct cause of the following exception:

Traceback (most recent call last):
  File "C:\Users\scary\AppData\Local\Programs\Python\Python36\lib\site-packages\discord\client.py", line 442, in connect
    await self._connect()
  File "C:\Users\scary\AppData\Local\Programs\Python\Python36\lib\site-packages\discord\client.py", line 403, in _connect
    self.ws = await asyncio.wait_for(coro, timeout=180.0, loop=self.loop)
  File "C:\Users\scary\AppData\Local\Programs\Python\Python36\lib\asyncio\tasks.py", line 358, in wait_for
    return fut.result()
  File "C:\Users\scary\AppData\Local\Programs\Python\Python36\lib\site-packages\discord\gateway.py", line 224, in from_client
    gateway = await client.http.get_gateway()
  File "C:\Users\scary\AppData\Local\Programs\Python\Python36\lib\site-packages\discord\http.py", line 788, in get_gateway
    data = await self.request(Route('GET', '/gateway'))
  File "C:\Users\scary\AppData\Local\Programs\Python\Python36\lib\site-packages\discord\http.py", line 158, in request
    async with self.__session.request(method, url, **kwargs) as r:
  File "C:\Users\scary\AppData\Local\Programs\Python\Python36\lib\site-packages\aiohttp\client.py", line 1005, in __aenter__
    self._resp = await self._coro
  File "C:\Users\scary\AppData\Local\Programs\Python\Python36\lib\site-packages\aiohttp\client.py", line 476, in _request
    timeout=real_timeout
  File "C:\Users\scary\AppData\Local\Programs\Python\Python36\lib\site-packages\aiohttp\connector.py", line 522, in connect
    proto = await self._create_connection(req, traces, timeout)
  File "C:\Users\scary\AppData\Local\Programs\Python\Python36\lib\site-packages\aiohttp\connector.py", line 854, in _create_connection
    req, traces, timeout)
  File "C:\Users\scary\AppData\Local\Programs\Python\Python36\lib\site-packages\aiohttp\connector.py", line 959, in _create_direct_connection
    raise ClientConnectorError(req.connection_key, exc) from exc
aiohttp.client_exceptions.ClientConnectorError: Cannot connect to host discordapp.com:443 ssl:None [getaddrinfo failed]
INFO:discord.client:logging in using static token
INFO:discord.gateway:Created websocket connected to wss://gateway.discord.gg?encoding=json&v=6&compress=zlib-stream
INFO:discord.gateway:Shard ID None has sent the IDENTIFY payload.
INFO:discord.gateway:Shard ID None has connected to Gateway: gateway-prd-main-0qwv, discord-sessions-prd-1-11 (Session ID: 9318e28ed5f3721439da0ee38ad3da06).
INFO:root:Logging in as:Party-Bot : 438288661398683650
INFO:discord.client:logging in using static token
INFO:discord.gateway:Created websocket connected to wss://gateway.discord.gg?encoding=json&v=6&compress=zlib-stream
INFO:discord.gateway:Shard ID None has sent the IDENTIFY payload.
INFO:discord.gateway:Shard ID None has connected to Gateway: gateway-prd-main-s0w2, discord-sessions-prd-1-10 (Session ID: 1be4881f3e81b6a16971eaa37b4764cb).
INFO:root:Logging in as:Party-Bot : 438288661398683650
WARNING:googleapiclient.discovery_cache:file_cache is unavailable when using oauth2client >= 4.0.0 or google-auth
Traceback (most recent call last):
  File "C:\Users\scary\AppData\Local\Programs\Python\Python36\lib\site-packages\googleapiclient\discovery_cache\__init__.py", line 36, in autodetect
    from google.appengine.api import memcache
ModuleNotFoundError: No module named 'google.appengine'

During handling of the above exception, another exception occurred:

Traceback (most recent call last):
  File "C:\Users\scary\AppData\Local\Programs\Python\Python36\lib\site-packages\googleapiclient\discovery_cache\file_cache.py", line 33, in <module>
    from oauth2client.contrib.locked_file import LockedFile
ModuleNotFoundError: No module named 'oauth2client'

During handling of the above exception, another exception occurred:

Traceback (most recent call last):
  File "C:\Users\scary\AppData\Local\Programs\Python\Python36\lib\site-packages\googleapiclient\discovery_cache\file_cache.py", line 37, in <module>
    from oauth2client.locked_file import LockedFile
ModuleNotFoundError: No module named 'oauth2client'

During handling of the above exception, another exception occurred:

Traceback (most recent call last):
  File "C:\Users\scary\AppData\Local\Programs\Python\Python36\lib\site-packages\googleapiclient\discovery_cache\__init__.py", line 41, in autodetect
    from . import file_cache
  File "C:\Users\scary\AppData\Local\Programs\Python\Python36\lib\site-packages\googleapiclient\discovery_cache\file_cache.py", line 41, in <module>
    'file_cache is unavailable when using oauth2client >= 4.0.0 or google-auth')
ImportError: file_cache is unavailable when using oauth2client >= 4.0.0 or google-auth
INFO:googleapiclient.discovery:URL being requested: GET https://www.googleapis.com/discovery/v1/apis/sheets/v4/rest
INFO:googleapiclient.discovery:URL being requested: POST https://sheets.googleapis.com/v4/spreadsheets/1dVZlsgtbUq0MGWV4kBg7m6Kwv2kQtbBd88KFHq9uumo/values/Session%20Tracker%21A%3AE:append?valueInputOption=USER_ENTERED&alt=json
INFO:root:Received |session| command from |Scarybone|
INFO:googleapiclient.discovery:URL being requested: POST https://sheets.googleapis.com/v4/spreadsheets/1dVZlsgtbUq0MGWV4kBg7m6Kwv2kQtbBd88KFHq9uumo/values/Session%20Tracker%21A%3AE:append?valueInputOption=USER_ENTERED&alt=json
INFO:root:Received |session| command from |Scarybone|
